Workbook

Sheet CL.SOL5--20251227
A1: ITEM NO. | B1: LINE NO. | C1: SHEET | D1: REV.A | E1: REV.0 | F1: REV.1 | G1: REMARK | H1: LINE NO.fix | I1: LINE No.1 | J1: DATE | K1: REV | L1: NumSheets | M1: REMARK.2 | N1: chk.NumSheets
A2: 1 | B2: CW-22101-2"-S1P1 | C2: 3 | D2: 45947 | E2: 45973 | H2: CW-22101-2"-S1P1 | I2: =_xlfn.LET(_xlpm.pos,IF(ISNUMBER(FIND("TRIM",B2)), 3, 2), _xlfn.TEXTBEFORE(B2, "-", _xlpm.pos)) -> CW-22101 | J2: =_xlfn.XLOOKUP("*",D2:F2,D2:F2,"",-1) -> 45973 | K2: =_xlfn.TEXTAFTER(_xlfn.XLOOKUP(J2,2:2,$1:$1), ".") -> 0 | L2: {=VALUE(_xlfn.IFS(ISERROR(FIND("(",C2,1)),C2,TRUE,MID(C2,FIND("(",C2,1)+1,LEN(C2)-FIND("(",C2,1)-1)))} -> 3 | N2: =_xlfn.LET(_xlpm.count, _xlfn.MAXIFS('DWG NO.ALL'!D:D,'DWG NO.ALL'!B:B,I2), IF(_xlpm.count=L2, "-", _xlpm.count)) -> -
A3: 2 | B3: CW-22102-2"-S1P1 | C3: 3 | D3: 45947 | E3: 45973 | H3: CW-22102-2"-S1P1 | I3: =_xlfn.LET(_xlpm.pos,IF(ISNUMBER(FIND("TRIM",B3)), 3, 2), _xlfn.TEXTBEFORE(B3, "-", _xlpm.pos)) -> CW-22102 | J3: =_xlfn.XLOOKUP("*",D3:F3,D3:F3,"",-1) -> 45973 | K3: =_xlfn.TEXTAFTER(_xlfn.XLOOKUP(J3,3:3,$1:$1), ".") -> 0 | L3: {=VALUE(_xlfn.IFS(ISERROR(FIND("(",C3,1)),C3,TRUE,MID(C3,FIND("(",C3,1)+1,LEN(C3)-FIND("(",C3,1)-1)))} -> 3 | N3: =_xlfn.LET(_xlpm.count, _xlfn.MAXIFS('DWG NO.ALL'!D:D,'DWG NO.ALL'!B:B,I3), IF(_xlpm.count=L3, "-", _xlpm.count)) -> -
A4: 3 | B4: CW-22103-1"-S1P1 | C4: 2 | D4: 45947 | E4: 45973 | H4: CW-22103-1"-S1P1 | I4: =_xlfn.LET(_xlpm.pos,IF(ISNUMBER(FIND("TRIM",B4)), 3, 2), _xlfn.TEXTBEFORE(B4, "-", _xlpm.pos)) -> CW-22103 | J4: =_xlfn.XLOOKUP("*",D4:F4,D4:F4,"",-1) -> 45973 | K4: =_xlfn.TEXTAFTER(_xlfn.XLOOKUP(J4,4:4,$1:$1), ".") -> 0 | L4: {=VALUE(_xlfn.IFS(ISERROR(FIND("(",C4,1)),C4,TRUE,MID(C4,FIND("(",C4,1)+1,LEN(C4)-FIND("(",C4,1)-1)))} -> 2 | N4: =_xlfn.LET(_xlpm.count, _xlfn.MAXIFS('DWG NO.ALL'!D:D,'DWG NO.ALL'!B:B,I4), IF(_xlpm.count=L4, "-", _xlpm.count)) -> -
A5: 4 | B5: CW-22104-1"-S1P1 | C5: 3 | D5: 45947 | E5: 45973 | H5: CW-22104-1"-S1P1 | I5: =_xlfn.LET(_xlpm.pos,IF(ISNUMBER(FIND("TRIM",B5)), 3, 2), _xlfn.TEXTBEFORE(B5, "-", _xlpm.pos)) -> CW-22104 | J5: =_xlfn.XLOOKUP("*",D5:F5,D5:F5,"",-1) -> 45973 | K5: =_xlfn.TEXTAFTER(_xlfn.XLOOKUP(J5,5:5,$1:$1), ".") -> 0 | L5: {=VALUE(_xlfn.IFS(ISERROR(FIND("(",C5,1)),C5,TRUE,MID(C5,FIND("(",C5,1)+1,LEN(C5)-FIND("(",C5,1)-1)))} -> 3 | N5: =_xlfn.LET(_xlpm.count, _xlfn.MAXIFS('DWG NO.ALL'!D:D,'DWG NO.ALL'!B:B,I5), IF(_xlpm.count=L5, "-", _xlpm.count)) -> -
A6: 5 | B6: CW-22105-4"-S1P1 | C6: 2 | D6: 45947 | E6: 45973 | H6: CW-22105-4"-S1P1 | I6: =_xlfn.LET(_xlpm.pos,IF(ISNUMBER(FIND("TRIM",B6)), 3, 2), _xlfn.TEXTBEFORE(B6, "-", _xlpm.pos)) -> CW-22105 | J6: =_xlfn.XLOOKUP("*",D6:F6,D6:F6,"",-1) -> 45973 | K6: =_xlfn.TEXTAFTER(_xlfn.XLOOKUP(J6,6:6,$1:$1), ".") -> 0 | L6: {=VALUE(_xlfn.IFS(ISERROR(FIND("(",C6,1)),C6,TRUE,MID(C6,FIND("(",C6,1)+1,LEN(C6)-FIND("(",C6,1)-1)))} -> 2 | N6: =_xlfn.LET(_xlpm.count, _xlfn.MAXIFS('DWG NO.ALL'!D:D,'DWG NO.ALL'!B:B,I6), IF(_xlpm.count=L6, "-", _xlpm.count)) -> -
A7: 6 | B7: CW-22106-4"-S1P1 | C7: 3 | D7: 45947 | E7: 45973 | H7: CW-22106-4"-S1P1 | I7: =_xlfn.LET(_xlpm.pos,IF(ISNUMBER(FIND("TRIM",B7)), 3, 2), _xlfn.TEXTBEFORE(B7, "-", _xlpm.pos)) -> CW-22106 | J7: =_xlfn.XLOOKUP("*",D7:F7,D7:F7,"",-1) -> 45973 | K7: =_xlfn.TEXTAFTER(_xlfn.XLOOKUP(J7,7:7,$1:$1), ".") -> 0 | L7: {=VALUE(_xlfn.IFS(ISERROR(FIND("(",C7,1)),C7,TRUE,MID(C7,FIND("(",C7,1)+1,LEN(C7)-FIND("(",C7,1)-1)))} -> 3 | N7: =_xlfn.LET(_xlpm.count, _xlfn.MAXIFS('DWG NO.ALL'!D:D,'DWG NO.ALL'!B:B,I7), IF(_xlpm.count=L7, "-", _xlpm.count)) -> -
A8: 7 | B8: CW-22201-3"-S1P1 | C8: 3 | D8: 45947 | E8: 45973 | H8: CW-22201-3"-S1P1 | I8: =_xlfn.LET(_xlpm.pos,IF(ISNUMBER(FIND("TRIM",B8)), 3, 2), _xlfn.TEXTBEFORE(B8, "-", _xlpm.pos)) -> CW-22201 | J8: =_xlfn.XLOOKUP("*",D8:F8,D8:F8,"",-1) -> 45973 | K8: =_xlfn.TEXTAFTER(_xlfn.XLOOKUP(J8,8:8,$1:$1), ".") -> 0 | L8: {=VALUE(_xlfn.IFS(ISERROR(FIND("(",C8,1)),C8,TRUE,MID(C8,FIND("(",C8,1)+1,LEN(C8)-FIND("(",C8,1)-1)))} -> 3 | N8: =_xlfn.LET(_xlpm.count, _xlfn.MAXIFS('DWG NO.ALL'!D:D,'DWG NO.ALL'!B:B,I8), IF(_xlpm.count=L8, "-", _xlpm.count)) -> -
A9: 8 | B9: CW-22202-3"-S1P1 | C9: 3 | D9: 45947 | E9: 45973 | H9: CW-22202-3"-S1P1 | I9: =_xlfn.LET(_xlpm.pos,IF(ISNUMBER(FIND("TRIM",B9)), 3, 2), _xlfn.TEXTBEFORE(B9, "-", _xlpm.pos)) -> CW-22202 | J9: =_xlfn.XLOOKUP("*",D9:F9,D9:F9,"",-1) -> 45973 | K9: =_xlfn.TEXTAFTER(_xlfn.XLOOKUP(J9,9:9,$1:$1), ".") -> 0 | L9: {=VALUE(_xlfn.IFS(ISERROR(FIND("(",C9,1)),C9,TRUE,MID(C9,FIND("(",C9,1)+1,LEN(C9)-FIND("(",C9,1)-1)))} -> 3 | N9: =_xlfn.LET(_xlpm.count, _xlfn.MAXIFS('DWG NO.ALL'!D:D,'DWG NO.ALL'!B:B,I9), IF(_xlpm.count=L9, "-", _xlpm.count)) -> -
A10: 9 | B10: CW-22203-2"-S1P1 | C10: 2 | D10: 45947 | E10: 45973 | H10: CW-22203-2"-S1P1 | I10: =_xlfn.LET(_xlpm.pos,IF(ISNUMBER(FIND("TRIM",B10)), 3, 2), _xlfn.TEXTBEFORE(B10, "-", _xlpm.pos)) -> CW-22203 | J10: =_xlfn.XLOOKUP("*",D10:F10,D10:F10,"",-1) -> 45973 | K10: =_xlfn.TEXTAFTER(_xlfn.XLOOKUP(J10,10:10,$1:$1), ".") -> 0 | L10: {=VALUE(_xlfn.IFS(ISERROR(FIND("(",C10,1)),C10,TRUE,MID(C10,FIND("(",C10,1)+1,LEN(C10)-FIND("(",C10,1)-1)))} -> 2 | N10: =_xlfn.LET(_xlpm.count, _xlfn.MAXIFS('DWG NO.ALL'!D:D,'DWG NO.ALL'!B:B,I10), IF(_xlpm.count=L10, "-", _xlpm.count)) -> -
A11: 10 | B11: CW-22204-2"-S1P1 | C11: 4 | D11: 45947 | E11: 45973 | H11: CW-22204-2"-S1P1 | I11: =_xlfn.LET(_xlpm.pos,IF(ISNUMBER(FIND("TRIM",B11)), 3, 2), _xlfn.TEXTBEFORE(B11, "-", _xlpm.pos)) -> CW-22204 | J11: =_xlfn.XLOOKUP("*",D11:F11,D11:F11,"",-1) -> 45973 | K11: =_xlfn.TEXTAFTER(_xlfn.XLOOKUP(J11,11:11,$1:$1), ".") -> 0 | L11: {=VALUE(_xlfn.IFS(ISERROR(FIND("(",C11,1)),C11,TRUE,MID(C11,FIND("(",C11,1)+1,LEN(C11)-FIND("(",C11,1)-1)))} -> 4 | N11: =_xlfn.LET(_xlpm.count, _xlfn.MAXIFS('DWG NO.ALL'!D:D,'DWG NO.ALL'!B:B,I11), IF(_xlpm.count=L11, "-", _xlpm.count)) -> -
A12: 11 | B12: CW-22205-6"-S1P1 | C12: 2 | D12: 45947 | E12: 45973 | H12: CW-22205-6"-S1P1 | I12: =_xlfn.LET(_xlpm.pos,IF(ISNUMBER(FIND("TRIM",B12)), 3, 2), _xlfn.TEXTBEFORE(B12, "-", _xlpm.pos)) -> CW-22205 | J12: =_xlfn.XLOOKUP("*",D12:F12,D12:F12,"",-1) -> 45973 | K12: =_xlfn.TEXTAFTER(_xlfn.XLOOKUP(J12,12:12,$1:$1), ".") -> 0 | L12: {=VALUE(_xlfn.IFS(ISERROR(FIND("(",C12,1)),C12,TRUE,MID(C12,FIND("(",C12,1)+1,LEN(C12)-FIND("(",C12,1)-1)))} -> 2 | N12: =_xlfn.LET(_xlpm.count, _xlfn.MAXIFS('DWG NO.ALL'!D:D,'DWG NO.ALL'!B:B,I12), IF(_xlpm.count=L12, "-", _xlpm.count)) -> -
A13: 12 | B13: CW-22206-6"-S1P1 | C13: 3 | D13: 45947 | E13: 45973 | H13: CW-22206-6"-S1P1 | I13: =_xlfn.LET(_xlpm.pos,IF(ISNUMBER(FIND("TRIM",B13)), 3, 2), _xlfn.TEXTBEFORE(B13, "-", _xlpm.pos)) -> CW-22206 | J13: =_xlfn.XLOOKUP("*",D13:F13,D13:F13,"",-1) -> 45973 | K13: =_xlfn.TEXTAFTER(_xlfn.XLOOKUP(J13,13:13,$1:$1), ".") -> 0 | L13: {=VALUE(_xlfn.IFS(ISERROR(FIND("(",C13,1)),C13,TRUE,MID(C13,FIND("(",C13,1)+1,LEN(C13)-FIND("(",C13,1)-1)))} -> 3 | N13: =_xlfn.LET(_xlpm.count, _xlfn.MAXIFS('DWG NO.ALL'!D:D,'DWG NO.ALL'!B:B,I13), IF(_xlpm.count=L13, "-", _xlpm.count)) -> -
A14: 13 | B14: CW-22351-8"-S1P1 | C14: 2 | D14: 45947 | E14: 45973 | H14: CW-22351-8"-S1P1 | I14: =_xlfn.LET(_xlpm.pos,IF(ISNUMBER(FIND("TRIM",B14)), 3, 2), _xlfn.TEXTBEFORE(B14, "-", _xlpm.pos)) -> CW-22351 | J14: =_xlfn.XLOOKUP("*",D14:F14,D14:F14,"",-1) -> 45973 | K14: =_xlfn.TEXTAFTER(_xlfn.XLOOKUP(J14,14:14,$1:$1), ".") -> 0 | L14: {=VALUE(_xlfn.IFS(ISERROR(FIND("(",C14,1)),C14,TRUE,MID(C14,FIND("(",C14,1)+1,LEN(C14)-FIND("(",C14,1)-1)))} -> 2 | N14: =_xlfn.LET(_xlpm.count, _xlfn.MAXIFS('DWG NO.ALL'!D:D,'DWG NO.ALL'!B:B,I14), IF(_xlpm.count=L14, "-", _xlpm.count)) -> -
A15: 14 | B15: CW-22352-8"-S1P1 | C15: 2 | D15: 45947 | E15: 45973 | H15: CW-22352-8"-S1P1 | I15: =_xlfn.LET(_xlpm.pos,IF(ISNUMBER(FIND("TRIM",B15)), 3, 2), _xlfn.TEXTBEFORE(B15, "-", _xlpm.pos)) -> CW-22352 | J15: =_xlfn.XLOOKUP("*",D15:F15,D15:F15,"",-1) -> 45973 | K15: =_xlfn.TEXTAFTER(_xlfn.XLOOKUP(J15,15:15,$1:$1), ".") -> 0 | L15: {=VALUE(_xlfn.IFS(ISERROR(FIND("(",C15,1)),C15,TRUE,MID(C15,FIND("(",C15,1)+1,LEN(C15)-FIND("(",C15,1)-1)))} -> 2 | N15: =_xlfn.LET(_xlpm.count, _xlfn.MAXIFS('DWG NO.ALL'!D:D,'DWG NO.ALL'!B:B,I15), IF(_xlpm.count=L15, "-", _xlpm.count)) -> -
A16: 15 | B16: FO-903A01-2"-S1P1F | C16: 5 | D16: 45947 | E16: 45973 | H16: FO-903A01-2"-S1P1F | I16: =_xlfn.LET(_xlpm.pos,IF(ISNUMBER(FIND("TRIM",B16)), 3, 2), _xlfn.TEXTBEFORE(B16, "-", _xlpm.pos)) -> FO-903A01 | J16: =_xlfn.XLOOKUP("*",D16:F16,D16:F16,"",-1) -> 45973 | K16: =_xlfn.TEXTAFTER(_xlfn.XLOOKUP(J16,16:16,$1:$1), ".") -> 0 | L16: {=VALUE(_xlfn.IFS(ISERROR(FIND("(",C16,1)),C16,TRUE,MID(C16,FIND("(",C16,1)+1,LEN(C16)-FIND("(",C16,1)-1)))} -> 5 | N16: =_xlfn.LET(_xlpm.count, _xlfn.MAXIFS('DWG NO.ALL'!D:D,'DWG NO.ALL'!B:B,I16), IF(_xlpm.count=L16, "-", _xlpm.count)) -> -
A17: 16 | B17: FO-903A02-1/2"-S1P1F | C17: 5 | D17: 45947 | E17: 45973 | H17: FO-903A02-1/2"-S1P1F | I17: =_xlfn.LET(_xlpm.pos,IF(ISNUMBER(FIND("TRIM",B17)), 3, 2), _xlfn.TEXTBEFORE(B17, "-", _xlpm.pos)) -> FO-903A02 | J17: =_xlfn.XLOOKUP("*",D17:F17,D17:F17,"",-1) -> 45973 | K17: =_xlfn.TEXTAFTER(_xlfn.XLOOKUP(J17,17:17,$1:$1), ".") -> 0 | L17: {=VALUE(_xlfn.IFS(ISERROR(FIND("(",C17,1)),C17,TRUE,MID(C17,FIND("(",C17,1)+1,LEN(C17)-FIND("(",C17,1)-1)))} -> 5 | N17: =_xlfn.LET(_xlpm.count, _xlfn.MAXIFS('DWG NO.ALL'!D:D,'DWG NO.ALL'!B:B,I17), IF(_xlpm.count=L17, "-", _xlpm.count)) -> -
A18: 17 | B18: FO-903A03-1.1/2"-S1P1F | C18: 1 | D18: 45947 | E18: 45973 | H18: FO-903A03-1.1/2"-S1P1F | I18: =_xlfn.LET(_xlpm.pos,IF(ISNUMBER(FIND("TRIM",B18)), 3, 2), _xlfn.TEXTBEFORE(B18, "-", _xlpm.pos)) -> FO-903A03 | J18: =_xlfn.XLOOKUP("*",D18:F18,D18:F18,"",-1) -> 45973 | K18: =_xlfn.TEXTAFTER(_xlfn.XLOOKUP(J18,18:18,$1:$1), ".") -> 0 | L18: {=VALUE(_xlfn.IFS(ISERROR(FIND("(",C18,1)),C18,TRUE,MID(C18,FIND("(",C18,1)+1,LEN(C18)-FIND("(",C18,1)-1)))} -> 1 | N18: =_xlfn.LET(_xlpm.count, _xlfn.MAXIFS('DWG NO.ALL'!D:D,'DWG NO.ALL'!B:B,I18), IF(_xlpm.count=L18, "-", _xlpm.count)) -> -
A19: 18 | B19: FO-903A04-2"-S1P1F | C19: 1 | D19: 45947 | E19: 45973 | H19: FO-903A04-2"-S1P1F | I19: =_xlfn.LET(_xlpm.pos,IF(ISNUMBER(FIND("TRIM",B19)), 3, 2), _xlfn.TEXTBEFORE(B19, "-", _xlpm.pos)) -> FO-903A04 | J19: =_xlfn.XLOOKUP("*",D19:F19,D19:F19,"",-1) -> 45973 | K19: =_xlfn.TEXTAFTER(_xlfn.XLOOKUP(J19,19:19,$1:$1), ".") -> 0 | L19: {=VALUE(_xlfn.IFS(ISERROR(FIND("(",C19,1)),C19,TRUE,MID(C19,FIND("(",C19,1)+1,LEN(C19)-FIND("(",C19,1)-1)))} -> 1 | N19: =_xlfn.LET(_xlpm.count, _xlfn.MAXIFS('DWG NO.ALL'!D:D,'DWG NO.ALL'!B:B,I19), IF(_xlpm.count=L19, "-", _xlpm.count)) -> -
A20: 19 | B20: FO-903A05-1"-S1P1F | C20: 1 | D20: 45947 | E20: 45973 | H20: FO-903A05-1"-S1P1F | I20: =_xlfn.LET(_xlpm.pos,IF(ISNUMBER(FIND("TRIM",B20)), 3, 2), _xlfn.TEXTBEFORE(B20, "-", _xlpm.pos)) -> FO-903A05 | J20: =_xlfn.XLOOKUP("*",D20:F20,D20:F20,"",-1) -> 45973 | K20: =_xlfn.TEXTAFTER(_xlfn.XLOOKUP(J20,20:20,$1:$1), ".") -> 0 | L20: {=VALUE(_xlfn.IFS(ISERROR(FIND("(",C20,1)),C20,TRUE,MID(C20,FIND("(",C20,1)+1,LEN(C20)-FIND("(",C20,1)-1)))} -> 1 | N20: =_xlfn.LET(_xlpm.count, _xlfn.MAXIFS('DWG NO.ALL'!D:D,'DWG NO.ALL'!B:B,I20), IF(_xlpm.count=L20, "-", _xlpm.count)) -> -
A21: 20 | B21: FO-903A06-1/2"-S1P1F | C21: 1 | D21: 45947 | E21: 45973 | H21: FO-903A06-1/2"-S1P1F | I21: =_xlfn.LET(_xlpm.pos,IF(ISNUMBER(FIND("TRIM",B21)), 3, 2), _xlfn.TEXTBEFORE(B21, "-", _xlpm.pos)) -> FO-903A06 | J21: =_xlfn.XLOOKUP("*",D21:F21,D21:F21,"",-1) -> 45973 | K21: =_xlfn.TEXTAFTER(_xlfn.XLOOKUP(J21,21:21,$1:$1), ".") -> 0 | L21: {=VALUE(_xlfn.IFS(ISERROR(FIND("(",C21,1)),C21,TRUE,MID(C21,FIND("(",C21,1)+1,LEN(C21)-FIND("(",C21,1)-1)))} -> 1 | N21: =_xlfn.LET(_xlpm.count, _xlfn.MAXIFS('DWG NO.ALL'!D:D,'DWG NO.ALL'!B:B,I21), IF(_xlpm.count=L21, "-", _xlpm.count)) -> -
A22: 21 | B22: FO-903A07-1/2"-S1P1F | C22: 1 | D22: 45947 | E22: 45973 | H22: FO-903A07-1/2"-S1P1F | I22: =_xlfn.LET(_xlpm.pos,IF(ISNUMBER(FIND("TRIM",B22)), 3, 2), _xlfn.TEXTBEFORE(B22, "-", _xlpm.pos)) -> FO-903A07 | J22: =_xlfn.XLOOKUP("*",D22:F22,D22:F22,"",-1) -> 45973 | K22: =_xlfn.TEXTAFTER(_xlfn.XLOOKUP(J22,22:22,$1:$1), ".") -> 0 | L22: {=VALUE(_xlfn.IFS(ISERROR(FIND("(",C22,1)),C22,TRUE,MID(C22,FIND("(",C22,1)+1,LEN(C22)-FIND("(",C22,1)-1)))} -> 1 | N22: =_xlfn.LET(_xlpm.count, _xlfn.MAXIFS('DWG NO.ALL'!D:D,'DWG NO.ALL'!B:B,I22), IF(_xlpm.count=L22, "-", _xlpm.count)) -> -
A23: 22 | B23: FO-903A08-1"-S1P1F | C23: 1 | D23: 45947 | E23: 45973 | H23: FO-903A08-1"-S1P1F | I23: =_xlfn.LET(_xlpm.pos,IF(ISNUMBER(FIND("TRIM",B23)), 3, 2), _xlfn.TEXTBEFORE(B23, "-", _xlpm.pos)) -> FO-903A08 | J23: =_xlfn.XLOOKUP("*",D23:F23,D23:F23,"",-1) -> 45973 | K23: =_xlfn.TEXTAFTER(_xlfn.XLOOKUP(J23,23:23,$1:$1), ".") -> 0 | L23: {=VALUE(_xlfn.IFS(ISERROR(FIND("(",C23,1)),C23,TRUE,MID(C23,FIND("(",C23,1)+1,LEN(C23)-FIND("(",C23,1)-1)))} -> 1 | N23: =_xlfn.LET(_xlpm.count, _xlfn.MAXIFS('DWG NO.ALL'!D:D,'DWG NO.ALL'!B:B,I23), IF(_xlpm.count=L23, "-", _xlpm.count)) -> -
A24: 23 | B24: HS-22101-1"-C3S1-HC2 | C24: 1 | D24: 45947 | E24: 45973 | H24: HS-22101-1"-C3S1-HC2 | I24: =_xlfn.LET(_xlpm.pos,IF(ISNUMBER(FIND("TRIM",B24)), 3, 2), _xlfn.TEXTBEFORE(B24, "-", _xlpm.pos)) -> HS-22101 | J24: =_xlfn.XLOOKUP("*",D24:F24,D24:F24,"",-1) -> 45973 | K24: =_xlfn.TEXTAFTER(_xlfn.XLOOKUP(J24,24:24,$1:$1), ".") -> 0 | L24: {=VALUE(_xlfn.IFS(ISERROR(FIND("(",C24,1)),C24,TRUE,MID(C24,FIND("(",C24,1)+1,LEN(C24)-FIND("(",C24,1)-1)))} -> 1 | N24: =_xlfn.LET(_xlpm.count, _xlfn.MAXIFS('DWG NO.ALL'!D:D,'DWG NO.ALL'!B:B,I24), IF(_xlpm.count=L24, "-", _xlpm.count)) -> -
A25: 24 | B25: HS-22201-2"-C3S1-HC2 | C25: 1 | D25: 45947 | E25: 45973 | H25: HS-22201-2"-C3S1-HC2 | I25: =_xlfn.LET(_xlpm.pos,IF(ISNUMBER(FIND("TRIM",B25)), 3, 2), _xlfn.TEXTBEFORE(B25, "-", _xlpm.pos)) -> HS-22201 | J25: =_xlfn.XLOOKUP("*",D25:F25,D25:F25,"",-1) -> 45973 | K25: =_xlfn.TEXTAFTER(_xlfn.XLOOKUP(J25,25:25,$1:$1), ".") -> 0 | L25: {=VALUE(_xlfn.IFS(ISERROR(FIND("(",C25,1)),C25,TRUE,MID(C25,FIND("(",C25,1)+1,LEN(C25)-FIND("(",C25,1)-1)))} -> 1 | N25: =_xlfn.LET(_xlpm.count, _xlfn.MAXIFS('DWG NO.ALL'!D:D,'DWG NO.ALL'!B:B,I25), IF(_xlpm.count=L25, "-", _xlpm.count)) -> -
A26: 25 | B26: HS-22341-4"-C3S1-HC2 | C26: 3 | D26: 45947 | E26: 45973 | H26: HS-22341-4"-C3S1-HC2 | I26: =_xlfn.LET(_xlpm.pos,IF(ISNUMBER(FIND("TRIM",B26)), 3, 2), _xlfn.TEXTBEFORE(B26, "-", _xlpm.pos)) -> HS-22341 | J26: =_xlfn.XLOOKUP("*",D26:F26,D26:F26,"",-1) -> 45973 | K26: =_xlfn.TEXTAFTER(_xlfn.XLOOKUP(J26,26:26,$1:$1), ".") -> 0 | L26: {=VALUE(_xlfn.IFS(ISERROR(FIND("(",C26,1)),C26,TRUE,MID(C26,FIND("(",C26,1)+1,LEN(C26)-FIND("(",C26,1)-1)))} -> 3 | N26: =_xlfn.LET(_xlpm.count, _xlfn.MAXIFS('DWG NO.ALL'!D:D,'DWG NO.ALL'!B:B,I26), IF(_xlpm.count=L26, "-", _xlpm.count)) -> -
A27: 26 | B27: IA-22361-1.1/2"-S1P4 | C27: 3 | D27: 45947 | E27: 45973 | H27: IA-22361-1.1/2"-S1P4 | I27: =_xlfn.LET(_xlpm.pos,IF(ISNUMBER(FIND("TRIM",B27)), 3, 2), _xlfn.TEXTBEFORE(B27, "-", _xlpm.pos)) -> IA-22361 | J27: =_xlfn.XLOOKUP("*",D27:F27,D27:F27,"",-1) -> 45973 | K27: =_xlfn.TEXTAFTER(_xlfn.XLOOKUP(J27,27:27,$1:$1), ".") -> 0 | L27: {=VALUE(_xlfn.IFS(ISERROR(FIND("(",C27,1)),C27,TRUE,MID(C27,FIND("(",C27,1)+1,LEN(C27)-FIND("(",C27,1)-1)))} -> 3 | N27: =_xlfn.LET(_xlpm.count, _xlfn.MAXIFS('DWG NO.ALL'!D:D,'DWG NO.ALL'!B:B,I27), IF(_xlpm.count=L27, "-", _xlpm.count)) -> -
A28: 27 | B28: ICW-22101-2"-S1P1-C40 | C28: 2 | D28: 45947 | E28: 45973 | H28: ICW-22101-2"-S1P1-C40 | I28: =_xlfn.LET(_xlpm.pos,IF(ISNUMBER(FIND("TRIM",B28)), 3, 2), _xlfn.TEXTBEFORE(B28, "-", _xlpm.pos)) -> ICW-22101 | J28: =_xlfn.XLOOKUP("*",D28:F28,D28:F28,"",-1) -> 45973 | K28: =_xlfn.TEXTAFTER(_xlfn.XLOOKUP(J28,28:28,$1:$1), ".") -> 0 | L28: {=VALUE(_xlfn.IFS(ISERROR(FIND("(",C28,1)),C28,TRUE,MID(C28,FIND("(",C28,1)+1,LEN(C28)-FIND("(",C28,1)-1)))} -> 2 | N28: =_xlfn.LET(_xlpm.count, _xlfn.MAXIFS('DWG NO.ALL'!D:D,'DWG NO.ALL'!B:B,I28), IF(_xlpm.count=L28, "-", _xlpm.count)) -> -
A29: 28 | B29: ICW-22102-2"-S1P1-C40 | C29: 3 | D29: 45947 | E29: 45973 | H29: ICW-22102-2"-S1P1-C40 | I29: =_xlfn.LET(_xlpm.pos,IF(ISNUMBER(FIND("TRIM",B29)), 3, 2), _xlfn.TEXTBEFORE(B29, "-", _xlpm.pos)) -> ICW-22102 | J29: =_xlfn.XLOOKUP("*",D29:F29,D29:F29,"",-1) -> 45973 | K29: =_xlfn.TEXTAFTER(_xlfn.XLOOKUP(J29,29:29,$1:$1), ".") -> 0 | L29: {=VALUE(_xlfn.IFS(ISERROR(FIND("(",C29,1)),C29,TRUE,MID(C29,FIND("(",C29,1)+1,LEN(C29)-FIND("(",C29,1)-1)))} -> 3 | N29: =_xlfn.LET(_xlpm.count, _xlfn.MAXIFS('DWG NO.ALL'!D:D,'DWG NO.ALL'!B:B,I29), IF(_xlpm.count=L29, "-", _xlpm.count)) -> -
A30: 29 | B30: ICW-22107-1"-S1P1-C40 | C30: 1 | D30: 45947 | E30: 45973 | H30: ICW-22107-1"-S1P1-C40 | I30: =_xlfn.LET(_xlpm.pos,IF(ISNUMBER(FIND("TRIM",B30)), 3, 2), _xlfn.TEXTBEFORE(B30, "-", _xlpm.pos)) -> ICW-22107 | J30: =_xlfn.XLOOKUP("*",D30:F30,D30:F30,"",-1) -> 45973 | K30: =_xlfn.TEXTAFTER(_xlfn.XLOOKUP(J30,30:30,$1:$1), ".") -> 0 | L30: {=VALUE(_xlfn.IFS(ISERROR(FIND("(",C30,1)),C30,TRUE,MID(C30,FIND("(",C30,1)+1,LEN(C30)-FIND("(",C30,1)-1)))} -> 1 | N30: =_xlfn.LET(_xlpm.count, _xlfn.MAXIFS('DWG NO.ALL'!D:D,'DWG NO.ALL'!B:B,I30), IF(_xlpm.count=L30, "-", _xlpm.count)) -> -
A31: 30 | B31: ICW-22108-1"-S1P1-C40 | C31: 1 | D31: 45947 | E31: 45973 | H31: ICW-22108-1"-S1P1-C40 | I31: =_xlfn.LET(_xlpm.pos,IF(ISNUMBER(FIND("TRIM",B31)), 3, 2), _xlfn.TEXTBEFORE(B31, "-", _xlpm.pos)) -> ICW-22108 | J31: =_xlfn.XLOOKUP("*",D31:F31,D31:F31,"",-1) -> 45973 | K31: =_xlfn.TEXTAFTER(_xlfn.XLOOKUP(J31,31:31,$1:$1), ".") -> 0 | L31: {=VALUE(_xlfn.IFS(ISERROR(FIND("(",C31,1)),C31,TRUE,MID(C31,FIND("(",C31,1)+1,LEN(C31)-FIND("(",C31,1)-1)))} -> 1 | N31: =_xlfn.LET(_xlpm.count, _xlfn.MAXIFS('DWG NO.ALL'!D:D,'DWG NO.ALL'!B:B,I31), IF(_xlpm.count=L31, "-", _xlpm.count)) -> -
A32: 31 | B32: ICW-22109-1"-S1P1-C40 | C32: 1 | D32: 45947 | E32: 45973 | H32: ICW-22109-1"-S1P1-C40 | I32: =_xlfn.LET(_xlpm.pos,IF(ISNUMBER(FIND("TRIM",B32)), 3, 2), _xlfn.TEXTBEFORE(B32, "-", _xlpm.pos)) -> ICW-22109 | J32: =_xlfn.XLOOKUP("*",D32:F32,D32:F32,"",-1) -> 45973 | K32: =_xlfn.TEXTAFTER(_xlfn.XLOOKUP(J32,32:32,$1:$1), ".") -> 0 | L32: {=VALUE(_xlfn.IFS(ISERROR(FIND("(",C32,1)),C32,TRUE,MID(C32,FIND("(",C32,1)+1,LEN(C32)-FIND("(",C32,1)-1)))} -> 1 | N32: =_xlfn.LET(_xlpm.count, _xlfn.MAXIFS('DWG NO.ALL'!D:D,'DWG NO.ALL'!B:B,I32), IF(_xlpm.count=L32, "-", _xlpm.count)) -> -
A33: 32 | B33: ICW-22110-1"-S1P1-C40 | C33: 1 | D33: 45947 | E33: 45973 | H33: ICW-22110-1"-S1P1-C40 | I33: =_xlfn.LET(_xlpm.pos,IF(ISNUMBER(FIND("TRIM",B33)), 3, 2), _xlfn.TEXTBEFORE(B33, "-", _xlpm.pos)) -> ICW-22110 | J33: =_xlfn.XLOOKUP("*",D33:F33,D33:F33,"",-1) -> 45973 | K33: =_xlfn.TEXTAFTER(_xlfn.XLOOKUP(J33,33:33,$1:$1), ".") -> 0 | L33: {=VALUE(_xlfn.IFS(ISERROR(FIND("(",C33,1)),C33,TRUE,MID(C33,FIND("(",C33,1)+1,LEN(C33)-FIND("(",C33,1)-1)))} -> 1 | N33: =_xlfn.LET(_xlpm.count, _xlfn.MAXIFS('DWG NO.ALL'!D:D,'DWG NO.ALL'!B:B,I33), IF(_xlpm.count=L33, "-", _xlpm.count)) -> -
A34: 33 | B34: ICW-22201-3"-S1P1-C40 | C34: 2 | D34: 45947 | E34: 45973 | H34: ICW-22201-3"-S1P1-C40 | I34: =_xlfn.LET(_xlpm.pos,IF(ISNUMBER(FIND("TRIM",B34)), 3, 2), _xlfn.TEXTBEFORE(B34, "-", _xlpm.pos)) -> ICW-22201 | J34: =_xlfn.XLOOKUP("*",D34:F34,D34:F34,"",-1) -> 45973 | K34: =_xlfn.TEXTAFTER(_xlfn.XLOOKUP(J34,34:34,$1:$1), ".") -> 0 | L34: {=VALUE(_xlfn.IFS(ISERROR(FIND("(",C34,1)),C34,TRUE,MID(C34,FIND("(",C34,1)+1,LEN(C34)-FIND("(",C34,1)-1)))} -> 2 | N34: =_xlfn.LET(_xlpm.count, _xlfn.MAXIFS('DWG NO.ALL'!D:D,'DWG NO.ALL'!B:B,I34), IF(_xlpm.count=L34, "-", _xlpm.count)) -> -
A35: 34 | B35: ICW-22202-3"-S1P1-C40 | C35: 2 | D35: 45947 | E35: 45973 | H35: ICW-22202-3"-S1P1-C40 | I35: =_xlfn.LET(_xlpm.pos,IF(ISNUMBER(FIND("TRIM",B35)), 3, 2), _xlfn.TEXTBEFORE(B35, "-", _xlpm.pos)) -> ICW-22202 | J35: =_xlfn.XLOOKUP("*",D35:F35,D35:F35,"",-1) -> 45973 | K35: =_xlfn.TEXTAFTER(_xlfn.XLOOKUP(J35,35:35,$1:$1), ".") -> 0 | L35: {=VALUE(_xlfn.IFS(ISERROR(FIND("(",C35,1)),C35,TRUE,MID(C35,FIND("(",C35,1)+1,LEN(C35)-FIND("(",C35,1)-1)))} -> 2 | N35: =_xlfn.LET(_xlpm.count, _xlfn.MAXIFS('DWG NO.ALL'!D:D,'DWG NO.ALL'!B:B,I35), IF(_xlpm.count=L35, "-", _xlpm.count)) -> -
A36: 35 | B36: ICW-22207-1"-S1P1-C40 | C36: 1 | D36: 45947 | E36: 45973 | H36: ICW-22207-1"-S1P1-C40 | I36: =_xlfn.LET(_xlpm.pos,IF(ISNUMBER(FIND("TRIM",B36)), 3, 2), _xlfn.TEXTBEFORE(B36, "-", _xlpm.pos)) -> ICW-22207 | J36: =_xlfn.XLOOKUP("*",D36:F36,D36:F36,"",-1) -> 45973 | K36: =_xlfn.TEXTAFTER(_xlfn.XLOOKUP(J36,36:36,$1:$1), ".") -> 0 | L36: {=VALUE(_xlfn.IFS(ISERROR(FIND("(",C36,1)),C36,TRUE,MID(C36,FIND("(",C36,1)+1,LEN(C36)-FIND("(",C36,1)-1)))} -> 1 | N36: =_xlfn.LET(_xlpm.count, _xlfn.MAXIFS('DWG NO.ALL'!D:D,'DWG NO.ALL'!B:B,I36), IF(_xlpm.count=L36, "-", _xlpm.count)) -> -
A37: 36 | B37: ICW-22208-1"-S1P1-C40 | C37: 1 | D37: 45947 | E37: 45973 | H37: ICW-22208-1"-S1P1-C40 | I37: =_xlfn.LET(_xlpm.pos,IF(ISNUMBER(FIND("TRIM",B37)), 3, 2), _xlfn.TEXTBEFORE(B37, "-", _xlpm.pos)) -> ICW-22208 | J37: =_xlfn.XLOOKUP("*",D37:F37,D37:F37,"",-1) -> 45973 | K37: =_xlfn.TEXTAFTER(_xlfn.XLOOKUP(J37,37:37,$1:$1), ".") -> 0 | L37: {=VALUE(_xlfn.IFS(ISERROR(FIND("(",C37,1)),C37,TRUE,MID(C37,FIND("(",C37,1)+1,LEN(C37)-FIND("(",C37,1)-1)))} -> 1 | N37: =_xlfn.LET(_xlpm.count, _xlfn.MAXIFS('DWG NO.ALL'!D:D,'DWG NO.ALL'!B:B,I37), IF(_xlpm.count=L37, "-", _xlpm.count)) -> -
A38: 37 | B38: ICW-22352-4"-S1P1-C40 | C38: 2 | D38: 45947 | E38: 45973 | H38: ICW-22352-4"-S1P1-C40 | I38: =_xlfn.LET(_xlpm.pos,IF(ISNUMBER(FIND("TRIM",B38)), 3, 2), _xlfn.TEXTBEFORE(B38, "-", _xlpm.pos)) -> ICW-22352 | J38: =_xlfn.XLOOKUP("*",D38:F38,D38:F38,"",-1) -> 45973 | K38: =_xlfn.TEXTAFTER(_xlfn.XLOOKUP(J38,38:38,$1:$1), ".") -> 0 | L38: {=VALUE(_xlfn.IFS(ISERROR(FIND("(",C38,1)),C38,TRUE,MID(C38,FIND("(",C38,1)+1,LEN(C38)-FIND("(",C38,1)-1)))} -> 2 | N38: =_xlfn.LET(_xlpm.count, _xlfn.MAXIFS('DWG NO.ALL'!D:D,'DWG NO.ALL'!B:B,I38), IF(_xlpm.count=L38, "-", _xlpm.count)) -> -
A39: 38 | B39: ICW-22351-4"-S1P1-C40 | C39: 2 | D39: 45947 | E39: 45973 | H39: ICW-22351-4"-S1P1-C40 | I39: =_xlfn.LET(_xlpm.pos,IF(ISNUMBER(FIND("TRIM",B39)), 3, 2), _xlfn.TEXTBEFORE(B39, "-", _xlpm.pos)) -> ICW-22351 | J39: =_xlfn.XLOOKUP("*",D39:F39,D39:F39,"",-1) -> 45973 | K39: =_xlfn.TEXTAFTER(_xlfn.XLOOKUP(J39,39:39,$1:$1), ".") -> 0 | L39: {=VALUE(_xlfn.IFS(ISERROR(FIND("(",C39,1)),C39,TRUE,MID(C39,FIND("(",C39,1)+1,LEN(C39)-FIND("(",C39,1)-1)))} -> 2 | N39: =_xlfn.LET(_xlpm.count, _xlfn.MAXIFS('DWG NO.ALL'!D:D,'DWG NO.ALL'!B:B,I39), IF(_xlpm.count=L39, "-", _xlpm.count)) -> -
A40: 39 | B40: IW-22371-2"-C1A1 | C40: 3 | D40: 45947 | E40: 45973 | H40: IW-22371-2"-C1A1 | I40: =_xlfn.LET(_xlpm.pos,IF(ISNUMBER(FIND("TRIM",B40)), 3, 2), _xlfn.TEXTBEFORE(B40, "-", _xlpm.pos)) -> IW-22371 | J40: =_xlfn.XLOOKUP("*",D40:F40,D40:F40,"",-1) -> 45973 | K40: =_xlfn.TEXTAFTER(_xlfn.XLOOKUP(J40,40:40,$1:$1), ".") -> 0 | L40: {=VALUE(_xlfn.IFS(ISERROR(FIND("(",C40,1)),C40,TRUE,MID(C40,FIND("(",C40,1)+1,LEN(C40)-FIND("(",C40,1)-1)))} -> 3 | N40: =_xlfn.LET(_xlpm.count, _xlfn.MAXIFS('DWG NO.ALL'!D:D,'DWG NO.ALL'!B:B,I40), IF(_xlpm.count=L40, "-", _xlpm.count)) -> -
...

Sheet DWG NO.ALL
A1: file | B1: LINE NO. | C1: Revision | D1: SheetIndex | E1: NumSheets | F1: chk.NumSheets | G1: file_basename | H1: chk.rev | I1: 流水號 | J1: 管線編號
A2: CW-22101-S1P1-Rev0-001.pdf | B2: =_xlfn.LET(_xlpm.pos,IF(ISNUMBER(FIND("TRIM",A2)), 3, 2), _xlfn.TEXTBEFORE(A2, "-", _xlpm.pos)) -> CW-22101 | C2: =_xlfn.TEXTBEFORE(_xlfn.TEXTAFTER(A2,"-Rev"), "-") -> 0 | D2: =VALUE(_xlfn.TEXTBEFORE(_xlfn.TEXTAFTER(A2, "-", -1), ".")) -> 1 | E2: =_xlfn.MAXIFS(D:D,B:B,B2) -> 3 | F2: =_xlfn.LET(_xlpm.count, _xlfn.XLOOKUP(B2,'CL.SOL5--20251227'!I:I,'CL.SOL5--20251227'!L:L), IF(_xlpm.count=E2,"-", _xlpm.count)) -> - | G2: =_xlfn.TEXTBEFORE(A2,".") -> CW-22101-S1P1-Rev0-001 | H2: =_xlfn.LET(_xlpm.rev, _xlfn.XLOOKUP(B2,'CL.SOL5--20251227'!I:I,'CL.SOL5--20251227'!K:K), IF(_xlpm.rev=C2, "-", _xlpm.rev)) -> - | I2: 1 | J2: =_xlfn.XLOOKUP(B2,'CL.SOL5--20251227'!I:I,'CL.SOL5--20251227'!H:H) -> CW-22101-2"-S1P1
A3: CW-22101-S1P1-Rev0-002.pdf | B3: =_xlfn.LET(_xlpm.pos,IF(ISNUMBER(FIND("TRIM",A3)), 3, 2), _xlfn.TEXTBEFORE(A3, "-", _xlpm.pos)) -> CW-22101 | C3: =_xlfn.TEXTBEFORE(_xlfn.TEXTAFTER(A3,"-Rev"), "-") -> 0 | D3: =VALUE(_xlfn.TEXTBEFORE(_xlfn.TEXTAFTER(A3, "-", -1), ".")) -> 2 | E3: =_xlfn.MAXIFS(D:D,B:B,B3) -> 3 | F3: =_xlfn.LET(_xlpm.count, _xlfn.XLOOKUP(B3,'CL.SOL5--20251227'!I:I,'CL.SOL5--20251227'!L:L), IF(_xlpm.count=E3,"-", _xlpm.count)) -> - | G3: =_xlfn.TEXTBEFORE(A3,".") -> CW-22101-S1P1-Rev0-002 | H3: =_xlfn.LET(_xlpm.rev, _xlfn.XLOOKUP(B3,'CL.SOL5--20251227'!I:I,'CL.SOL5--20251227'!K:K), IF(_xlpm.rev=C3, "-", _xlpm.rev)) -> - | I3: 2 | J3: =_xlfn.XLOOKUP(B3,'CL.SOL5--20251227'!I:I,'CL.SOL5--20251227'!H:H) -> CW-22101-2"-S1P1
A4: CW-22101-S1P1-Rev0-003.pdf | B4: =_xlfn.LET(_xlpm.pos,IF(ISNUMBER(FIND("TRIM",A4)), 3, 2), _xlfn.TEXTBEFORE(A4, "-", _xlpm.pos)) -> CW-22101 | C4: =_xlfn.TEXTBEFORE(_xlfn.TEXTAFTER(A4,"-Rev"), "-") -> 0 | D4: =VALUE(_xlfn.TEXTBEFORE(_xlfn.TEXTAFTER(A4, "-", -1), ".")) -> 3 | E4: =_xlfn.MAXIFS(D:D,B:B,B4) -> 3 | F4: =_xlfn.LET(_xlpm.count, _xlfn.XLOOKUP(B4,'CL.SOL5--20251227'!I:I,'CL.SOL5--20251227'!L:L), IF(_xlpm.count=E4,"-", _xlpm.count)) -> - | G4: =_xlfn.TEXTBEFORE(A4,".") -> CW-22101-S1P1-Rev0-003 | H4: =_xlfn.LET(_xlpm.rev, _xlfn.XLOOKUP(B4,'CL.SOL5--20251227'!I:I,'CL.SOL5--20251227'!K:K), IF(_xlpm.rev=C4, "-", _xlpm.rev)) -> - | I4: 3 | J4: =_xlfn.XLOOKUP(B4,'CL.SOL5--20251227'!I:I,'CL.SOL5--20251227'!H:H) -> CW-22101-2"-S1P1
A5: CW-22102-S1P1-Rev0-001.pdf | B5: =_xlfn.LET(_xlpm.pos,IF(ISNUMBER(FIND("TRIM",A5)), 3, 2), _xlfn.TEXTBEFORE(A5, "-", _xlpm.pos)) -> CW-22102 | C5: =_xlfn.TEXTBEFORE(_xlfn.TEXTAFTER(A5,"-Rev"), "-") -> 0 | D5: =VALUE(_xlfn.TEXTBEFORE(_xlfn.TEXTAFTER(A5, "-", -1), ".")) -> 1 | E5: =_xlfn.MAXIFS(D:D,B:B,B5) -> 3 | F5: =_xlfn.LET(_xlpm.count, _xlfn.XLOOKUP(B5,'CL.SOL5--20251227'!I:I,'CL.SOL5--20251227'!L:L), IF(_xlpm.count=E5,"-", _xlpm.count)) -> - | G5: =_xlfn.TEXTBEFORE(A5,".") -> CW-22102-S1P1-Rev0-001 | H5: =_xlfn.LET(_xlpm.rev, _xlfn.XLOOKUP(B5,'CL.SOL5--20251227'!I:I,'CL.SOL5--20251227'!K:K), IF(_xlpm.rev=C5, "-", _xlpm.rev)) -> - | I5: 4 | J5: =_xlfn.XLOOKUP(B5,'CL.SOL5--20251227'!I:I,'CL.SOL5--20251227'!H:H) -> CW-22102-2"-S1P1
A6: CW-22102-S1P1-Rev0-002.pdf | B6: =_xlfn.LET(_xlpm.pos,IF(ISNUMBER(FIND("TRIM",A6)), 3, 2), _xlfn.TEXTBEFORE(A6, "-", _xlpm.pos)) -> CW-22102 | C6: =_xlfn.TEXTBEFORE(_xlfn.TEXTAFTER(A6,"-Rev"), "-") -> 0 | D6: =VALUE(_xlfn.TEXTBEFORE(_xlfn.TEXTAFTER(A6, "-", -1), ".")) -> 2 | E6: =_xlfn.MAXIFS(D:D,B:B,B6) -> 3 | F6: =_xlfn.LET(_xlpm.count, _xlfn.XLOOKUP(B6,'CL.SOL5--20251227'!I:I,'CL.SOL5--20251227'!L:L), IF(_xlpm.count=E6,"-", _xlpm.count)) -> - | G6: =_xlfn.TEXTBEFORE(A6,".") -> CW-22102-S1P1-Rev0-002 | H6: =_xlfn.LET(_xlpm.rev, _xlfn.XLOOKUP(B6,'CL.SOL5--20251227'!I:I,'CL.SOL5--20251227'!K:K), IF(_xlpm.rev=C6, "-", _xlpm.rev)) -> - | I6: 5 | J6: =_xlfn.XLOOKUP(B6,'CL.SOL5--20251227'!I:I,'CL.SOL5--20251227'!H:H) -> CW-22102-2"-S1P1
A7: CW-22102-S1P1-Rev0-003.pdf | B7: =_xlfn.LET(_xlpm.pos,IF(ISNUMBER(FIND("TRIM",A7)), 3, 2), _xlfn.TEXTBEFORE(A7, "-", _xlpm.pos)) -> CW-22102 | C7: =_xlfn.TEXTBEFORE(_xlfn.TEXTAFTER(A7,"-Rev"), "-") -> 0 | D7: =VALUE(_xlfn.TEXTBEFORE(_xlfn.TEXTAFTER(A7, "-", -1), ".")) -> 3 | E7: =_xlfn.MAXIFS(D:D,B:B,B7) -> 3 | F7: =_xlfn.LET(_xlpm.count, _xlfn.XLOOKUP(B7,'CL.SOL5--20251227'!I:I,'CL.SOL5--20251227'!L:L), IF(_xlpm.count=E7,"-", _xlpm.count)) -> - | G7: =_xlfn.TEXTBEFORE(A7,".") -> CW-22102-S1P1-Rev0-003 | H7: =_xlfn.LET(_xlpm.rev, _xlfn.XLOOKUP(B7,'CL.SOL5--20251227'!I:I,'CL.SOL5--20251227'!K:K), IF(_xlpm.rev=C7, "-", _xlpm.rev)) -> - | I7: 6 | J7: =_xlfn.XLOOKUP(B7,'CL.SOL5--20251227'!I:I,'CL.SOL5--20251227'!H:H) -> CW-22102-2"-S1P1
A8: CW-22103-S1P1-Rev0-001.pdf | B8: =_xlfn.LET(_xlpm.pos,IF(ISNUMBER(FIND("TRIM",A8)), 3, 2), _xlfn.TEXTBEFORE(A8, "-", _xlpm.pos)) -> CW-22103 | C8: =_xlfn.TEXTBEFORE(_xlfn.TEXTAFTER(A8,"-Rev"), "-") -> 0 | D8: =VALUE(_xlfn.TEXTBEFORE(_xlfn.TEXTAFTER(A8, "-", -1), ".")) -> 1 | E8: =_xlfn.MAXIFS(D:D,B:B,B8) -> 2 | F8: =_xlfn.LET(_xlpm.count, _xlfn.XLOOKUP(B8,'CL.SOL5--20251227'!I:I,'CL.SOL5--20251227'!L:L), IF(_xlpm.count=E8,"-", _xlpm.count)) -> - | G8: =_xlfn.TEXTBEFORE(A8,".") -> CW-22103-S1P1-Rev0-001 | H8: =_xlfn.LET(_xlpm.rev, _xlfn.XLOOKUP(B8,'CL.SOL5--20251227'!I:I,'CL.SOL5--20251227'!K:K), IF(_xlpm.rev=C8, "-", _xlpm.rev)) -> - | I8: 7 | J8: =_xlfn.XLOOKUP(B8,'CL.SOL5--20251227'!I:I,'CL.SOL5--20251227'!H:H) -> CW-22103-1"-S1P1
A9: CW-22103-S1P1-Rev0-002.pdf | B9: =_xlfn.LET(_xlpm.pos,IF(ISNUMBER(FIND("TRIM",A9)), 3, 2), _xlfn.TEXTBEFORE(A9, "-", _xlpm.pos)) -> CW-22103 | C9: =_xlfn.TEXTBEFORE(_xlfn.TEXTAFTER(A9,"-Rev"), "-") -> 0 | D9: =VALUE(_xlfn.TEXTBEFORE(_xlfn.TEXTAFTER(A9, "-", -1), ".")) -> 2 | E9: =_xlfn.MAXIFS(D:D,B:B,B9) -> 2 | F9: =_xlfn.LET(_xlpm.count, _xlfn.XLOOKUP(B9,'CL.SOL5--20251227'!I:I,'CL.SOL5--20251227'!L:L), IF(_xlpm.count=E9,"-", _xlpm.count)) -> - | G9: =_xlfn.TEXTBEFORE(A9,".") -> CW-22103-S1P1-Rev0-002 | H9: =_xlfn.LET(_xlpm.rev, _xlfn.XLOOKUP(B9,'CL.SOL5--20251227'!I:I,'CL.SOL5--20251227'!K:K), IF(_xlpm.rev=C9, "-", _xlpm.rev)) -> - | I9: 8 | J9: =_xlfn.XLOOKUP(B9,'CL.SOL5--20251227'!I:I,'CL.SOL5--20251227'!H:H) -> CW-22103-1"-S1P1
A10: CW-22104-S1P1-Rev0-001.pdf | B10: =_xlfn.LET(_xlpm.pos,IF(ISNUMBER(FIND("TRIM",A10)), 3, 2), _xlfn.TEXTBEFORE(A10, "-", _xlpm.pos)) -> CW-22104 | C10: =_xlfn.TEXTBEFORE(_xlfn.TEXTAFTER(A10,"-Rev"), "-") -> 0 | D10: =VALUE(_xlfn.TEXTBEFORE(_xlfn.TEXTAFTER(A10, "-", -1), ".")) -> 1 | E10: =_xlfn.MAXIFS(D:D,B:B,B10) -> 3 | F10: =_xlfn.LET(_xlpm.count, _xlfn.XLOOKUP(B10,'CL.SOL5--20251227'!I:I,'CL.SOL5--20251227'!L:L), IF(_xlpm.count=E10,"-", _xlpm.count)) -> - | G10: =_xlfn.TEXTBEFORE(A10,".") -> CW-22104-S1P1-Rev0-001 | H10: =_xlfn.LET(_xlpm.rev, _xlfn.XLOOKUP(B10,'CL.SOL5--20251227'!I:I,'CL.SOL5--20251227'!K:K), IF(_xlpm.rev=C10, "-", _xlpm.rev)) -> - | I10: 9 | J10: =_xlfn.XLOOKUP(B10,'CL.SOL5--20251227'!I:I,'CL.SOL5--20251227'!H:H) -> CW-22104-1"-S1P1
A11: CW-22104-S1P1-Rev0-002.pdf | B11: =_xlfn.LET(_xlpm.pos,IF(ISNUMBER(FIND("TRIM",A11)), 3, 2), _xlfn.TEXTBEFORE(A11, "-", _xlpm.pos)) -> CW-22104 | C11: =_xlfn.TEXTBEFORE(_xlfn.TEXTAFTER(A11,"-Rev"), "-") -> 0 | D11: =VALUE(_xlfn.TEXTBEFORE(_xlfn.TEXTAFTER(A11, "-", -1), ".")) -> 2 | E11: =_xlfn.MAXIFS(D:D,B:B,B11) -> 3 | F11: =_xlfn.LET(_xlpm.count, _xlfn.XLOOKUP(B11,'CL.SOL5--20251227'!I:I,'CL.SOL5--20251227'!L:L), IF(_xlpm.count=E11,"-", _xlpm.count)) -> - | G11: =_xlfn.TEXTBEFORE(A11,".") -> CW-22104-S1P1-Rev0-002 | H11: =_xlfn.LET(_xlpm.rev, _xlfn.XLOOKUP(B11,'CL.SOL5--20251227'!I:I,'CL.SOL5--20251227'!K:K), IF(_xlpm.rev=C11, "-", _xlpm.rev)) -> - | I11: 10 | J11: =_xlfn.XLOOKUP(B11,'CL.SOL5--20251227'!I:I,'CL.SOL5--20251227'!H:H) -> CW-22104-1"-S1P1
A12: CW-22104-S1P1-Rev0-003.pdf | B12: =_xlfn.LET(_xlpm.pos,IF(ISNUMBER(FIND("TRIM",A12)), 3, 2), _xlfn.TEXTBEFORE(A12, "-", _xlpm.pos)) -> CW-22104 | C12: =_xlfn.TEXTBEFORE(_xlfn.TEXTAFTER(A12,"-Rev"), "-") -> 0 | D12: =VALUE(_xlfn.TEXTBEFORE(_xlfn.TEXTAFTER(A12, "-", -1), ".")) -> 3 | E12: =_xlfn.MAXIFS(D:D,B:B,B12) -> 3 | F12: =_xlfn.LET(_xlpm.count, _xlfn.XLOOKUP(B12,'CL.SOL5--20251227'!I:I,'CL.SOL5--20251227'!L:L), IF(_xlpm.count=E12,"-", _xlpm.count)) -> - | G12: =_xlfn.TEXTBEFORE(A12,".") -> CW-22104-S1P1-Rev0-003 | H12: =_xlfn.LET(_xlpm.rev, _xlfn.XLOOKUP(B12,'CL.SOL5--20251227'!I:I,'CL.SOL5--20251227'!K:K), IF(_xlpm.rev=C12, "-", _xlpm.rev)) -> - | I12: 11 | J12: =_xlfn.XLOOKUP(B12,'CL.SOL5--20251227'!I:I,'CL.SOL5--20251227'!H:H) -> CW-22104-1"-S1P1
A13: CW-22105-S1P1-Rev0-001.pdf | B13: =_xlfn.LET(_xlpm.pos,IF(ISNUMBER(FIND("TRIM",A13)), 3, 2), _xlfn.TEXTBEFORE(A13, "-", _xlpm.pos)) -> CW-22105 | C13: =_xlfn.TEXTBEFORE(_xlfn.TEXTAFTER(A13,"-Rev"), "-") -> 0 | D13: =VALUE(_xlfn.TEXTBEFORE(_xlfn.TEXTAFTER(A13, "-", -1), ".")) -> 1 | E13: =_xlfn.MAXIFS(D:D,B:B,B13) -> 2 | F13: =_xlfn.LET(_xlpm.count, _xlfn.XLOOKUP(B13,'CL.SOL5--20251227'!I:I,'CL.SOL5--20251227'!L:L), IF(_xlpm.count=E13,"-", _xlpm.count)) -> - | G13: =_xlfn.TEXTBEFORE(A13,".") -> CW-22105-S1P1-Rev0-001 | H13: =_xlfn.LET(_xlpm.rev, _xlfn.XLOOKUP(B13,'CL.SOL5--20251227'!I:I,'CL.SOL5--20251227'!K:K), IF(_xlpm.rev=C13, "-", _xlpm.rev)) -> - | I13: 12 | J13: =_xlfn.XLOOKUP(B13,'CL.SOL5--20251227'!I:I,'CL.SOL5--20251227'!H:H) -> CW-22105-4"-S1P1
... A313: WW-22371-S1P4-Rev0-005.pdf | B313: =_xlfn.LET(_xlpm.pos,IF(ISNUMBER(FIND("TRIM",A313)), 3, 2), _xlfn.TEXTBEFORE(A313, "-", _xlpm.pos)) -> WW-22371 | C313: =_xlfn.TEXTBEFORE(_xlfn.TEXTAFTER(A313,"-Rev"), "-") -> 0 | D313: =VALUE(_xlfn.TEXTBEFORE(_xlfn.TEXTAFTER(A313, "-", -1), ".")) -> 5 | E313: =_xlfn.MAXIFS(D:D,B:B,B313) -> 5 | F313: =_xlfn.LET(_xlpm.count, _xlfn.XLOOKUP(B313,'CL.SOL5--20251227'!I:I,'CL.SOL5--20251227'!L:L), IF(_xlpm.count=E313,"-", _xlpm.count)) -> - | G313: =_xlfn.TEXTBEFORE(A313,".") -> WW-22371-S1P4-Rev0-005 | H313: =_xlfn.LET(_xlpm.rev, _xlfn.XLOOKUP(B313,'CL.SOL5--20251227'!I:I,'CL.SOL5--20251227'!K:K), IF(_xlpm.rev=C313, "-", _xlpm.rev)) -> - | I313: 312 | J313: =_xlfn.XLOOKUP(B313,'CL.SOL5--20251227'!I:I,'CL.SOL5--20251227'!H:H) -> WW-22371-1.1/2"-S1P4

Sheet 圖號清單
A1: 溶劑5廠ISO圖號清單-114.12.27
A3: 流水號 | B3: file_basename | C3: 管線編號 | D3: Revision
A4: 1 | B4: CW-22101-S1P1-Rev0-001 | C4: CW-22101-2"-S1P1 | D4: 0
A5: 2 | B5: CW-22101-S1P1-Rev0-002 | C5: CW-22101-2"-S1P1 | D5: 0
A6: 3 | B6: CW-22101-S1P1-Rev0-003 | C6: CW-22101-2"-S1P1 | D6: 0
A7: 4 | B7: CW-22102-S1P1-Rev0-001 | C7: CW-22102-2"-S1P1 | D7: 0
A8: 5 | B8: CW-22102-S1P1-Rev0-002 | C8: CW-22102-2"-S1P1 | D8: 0
A9: 6 | B9: CW-22102-S1P1-Rev0-003 | C9: CW-22102-2"-S1P1 | D9: 0
A10: 7 | B10: CW-22103-S1P1-Rev0-001 | C10: CW-22103-1"-S1P1 | D10: 0
A11: 8 | B11: CW-22103-S1P1-Rev0-002 | C11: CW-22103-1"-S1P1 | D11: 0
A12: 9 | B12: CW-22104-S1P1-Rev0-001 | C12: CW-22104-1"-S1P1 | D12: 0
A13: 10 | B13: CW-22104-S1P1-Rev0-002 | C13: CW-22104-1"-S1P1 | D13: 0
A14: 11 | B14: CW-22104-S1P1-Rev0-003 | C14: CW-22104-1"-S1P1 | D14: 0
A15: 12 | B15: CW-22105-S1P1-Rev0-001 | C15: CW-22105-4"-S1P1 | D15: 0
... A315: 312 | B315: WW-22371-S1P4-Rev0-005 | C315: WW-22371-1.1/2"-S1P4 | D315: 0
A316: 總計
